[2025-07-30T21:37:14.090+0000] {taskinstance.py:1956} INFO - Dependencies all met for dep_context=non-requeueable deps ti=<TaskInstance: pipeline_medallon.ejecutar_merge manual__2025-07-30T21:31:25+00:00 [queued]>
[2025-07-30T21:37:14.168+0000] {taskinstance.py:1956} INFO - Dependencies all met for dep_context=requeueable deps ti=<TaskInstance: pipeline_medallon.ejecutar_merge manual__2025-07-30T21:31:25+00:00 [queued]>
[2025-07-30T21:37:14.168+0000] {taskinstance.py:2170} INFO - Starting attempt 2 of 2
[2025-07-30T21:37:14.212+0000] {taskinstance.py:2191} INFO - Executing <Task(PostgresOperator): ejecutar_merge> on 2025-07-30 21:31:25+00:00
[2025-07-30T21:37:14.216+0000] {standard_task_runner.py:60} INFO - Started process 256 to run task
[2025-07-30T21:37:14.219+0000] {standard_task_runner.py:87} INFO - Running: ['airflow', 'tasks', 'run', 'pipeline_medallon', 'ejecutar_merge', 'manual__2025-07-30T21:31:25+00:00', '--job-id', '27', '--raw', '--subdir', 'DAGS_FOLDER/pipeline_medallon_dag.py', '--cfg-path', '/tmp/tmpl4y5fdgf']
[2025-07-30T21:37:14.221+0000] {standard_task_runner.py:88} INFO - Job 27: Subtask ejecutar_merge
[2025-07-30T21:37:14.308+0000] {task_command.py:423} INFO - Running <TaskInstance: pipeline_medallon.ejecutar_merge manual__2025-07-30T21:31:25+00:00 [running]> on host 70eaa744a05c
[2025-07-30T21:37:14.412+0000] {taskinstance.py:2480} INFO - Exporting env vars: AIRFLOW_CTX_DAG_OWNER='mateo.biasotto' AIRFLOW_CTX_DAG_ID='pipeline_medallon' AIRFLOW_CTX_TASK_ID='ejecutar_merge' AIRFLOW_CTX_EXECUTION_DATE='2025-07-30T21:31:25+00:00' AIRFLOW_CTX_TRY_NUMBER='2' AIRFLOW_CTX_DAG_RUN_ID='manual__2025-07-30T21:31:25+00:00'
[2025-07-30T21:37:14.413+0000] {sql.py:276} INFO - Executing: CALL merge_bulk_to_final();
[2025-07-30T21:37:14.432+0000] {taskinstance.py:2698} ERROR - Task failed with exception
Traceback (most recent call last):
  File "/home/airflow/.local/lib/python3.8/site-packages/airflow/models/taskinstance.py", line 433, in _execute_task
    result = execute_callable(context=context, **execute_callable_kwargs)
  File "/home/airflow/.local/lib/python3.8/site-packages/airflow/providers/common/sql/operators/sql.py", line 277, in execute
    hook = self.get_db_hook()
  File "/home/airflow/.local/lib/python3.8/site-packages/airflow/providers/common/sql/operators/sql.py", line 188, in get_db_hook
    return self._hook
  File "/usr/local/lib/python3.8/functools.py", line 967, in __get__
    val = self.func(instance)
  File "/home/airflow/.local/lib/python3.8/site-packages/airflow/providers/common/sql/operators/sql.py", line 150, in _hook
    conn = BaseHook.get_connection(conn_id)
  File "/home/airflow/.local/lib/python3.8/site-packages/airflow/hooks/base.py", line 82, in get_connection
    conn = Connection.get_connection_from_secrets(conn_id)
  File "/home/airflow/.local/lib/python3.8/site-packages/airflow/models/connection.py", line 479, in get_connection_from_secrets
    raise AirflowNotFoundException(f"The conn_id `{conn_id}` isn't defined")
airflow.exceptions.AirflowNotFoundException: The conn_id `postgres_medallon` isn't defined
[2025-07-30T21:37:14.436+0000] {taskinstance.py:1138} INFO - Marking task as FAILED. dag_id=pipeline_medallon, task_id=ejecutar_merge, execution_date=20250730T213125, start_date=20250730T213714, end_date=20250730T213714
[2025-07-30T21:37:14.470+0000] {standard_task_runner.py:107} ERROR - Failed to execute job 27 for task ejecutar_merge (The conn_id `postgres_medallon` isn't defined; 256)
[2025-07-30T21:37:14.514+0000] {local_task_job_runner.py:234} INFO - Task exited with return code 1
[2025-07-30T21:37:14.534+0000] {taskinstance.py:3280} INFO - 0 downstream tasks scheduled from follow-on schedule check
