[2025-07-30T20:10:54.098+0000] {taskinstance.py:1956} INFO - Dependencies all met for dep_context=non-requeueable deps ti=<TaskInstance: pipeline_medallon.cargar_bronze manual__2025-07-30T20:03:59+00:00 [queued]>
[2025-07-30T20:10:54.115+0000] {taskinstance.py:1956} INFO - Dependencies all met for dep_context=requeueable deps ti=<TaskInstance: pipeline_medallon.cargar_bronze manual__2025-07-30T20:03:59+00:00 [queued]>
[2025-07-30T20:10:54.116+0000] {taskinstance.py:2170} INFO - Starting attempt 2 of 2
[2025-07-30T20:10:54.156+0000] {taskinstance.py:2191} INFO - Executing <Task(BashOperator): cargar_bronze> on 2025-07-30 20:03:59+00:00
[2025-07-30T20:10:54.160+0000] {standard_task_runner.py:60} INFO - Started process 165 to run task
[2025-07-30T20:10:54.164+0000] {standard_task_runner.py:87} INFO - Running: ['airflow', 'tasks', 'run', 'pipeline_medallon', 'cargar_bronze', 'manual__2025-07-30T20:03:59+00:00', '--job-id', '4', '--raw', '--subdir', 'DAGS_FOLDER/pipeline_medallon_dag.py', '--cfg-path', '/tmp/tmp13z3jmae']
[2025-07-30T20:10:54.167+0000] {standard_task_runner.py:88} INFO - Job 4: Subtask cargar_bronze
[2025-07-30T20:10:54.247+0000] {task_command.py:423} INFO - Running <TaskInstance: pipeline_medallon.cargar_bronze manual__2025-07-30T20:03:59+00:00 [running]> on host 2a163dc77c1e
[2025-07-30T20:10:54.343+0000] {taskinstance.py:2480} INFO - Exporting env vars: AIRFLOW_CTX_DAG_OWNER='mateo.biasotto' AIRFLOW_CTX_DAG_ID='pipeline_medallon' AIRFLOW_CTX_TASK_ID='cargar_bronze' AIRFLOW_CTX_EXECUTION_DATE='2025-07-30T20:03:59+00:00' AIRFLOW_CTX_TRY_NUMBER='2' AIRFLOW_CTX_DAG_RUN_ID='manual__2025-07-30T20:03:59+00:00'
[2025-07-30T20:10:54.344+0000] {subprocess.py:63} INFO - Tmp dir root location: /tmp
[2025-07-30T20:10:54.345+0000] {subprocess.py:75} INFO - Running command: ['/usr/bin/bash', '-c', 'python3 /opt/airflow/scripts/01_local_a_bronze.py']
[2025-07-30T20:10:54.353+0000] {subprocess.py:86} INFO - Output:
[2025-07-30T20:11:00.597+0000] {subprocess.py:93} INFO - Traceback (most recent call last):
[2025-07-30T20:11:00.597+0000] {subprocess.py:93} INFO -   File "/home/airflow/.local/lib/python3.8/site-packages/urllib3/connection.py", line 174, in _new_conn
[2025-07-30T20:11:00.598+0000] {subprocess.py:93} INFO -     conn = connection.create_connection(
[2025-07-30T20:11:00.598+0000] {subprocess.py:93} INFO -   File "/home/airflow/.local/lib/python3.8/site-packages/urllib3/util/connection.py", line 95, in create_connection
[2025-07-30T20:11:00.599+0000] {subprocess.py:93} INFO -     raise err
[2025-07-30T20:11:00.599+0000] {subprocess.py:93} INFO -   File "/home/airflow/.local/lib/python3.8/site-packages/urllib3/util/connection.py", line 85, in create_connection
[2025-07-30T20:11:00.600+0000] {subprocess.py:93} INFO -     sock.connect(sa)
[2025-07-30T20:11:00.600+0000] {subprocess.py:93} INFO - ConnectionRefusedError: [Errno 111] Connection refused
[2025-07-30T20:11:00.601+0000] {subprocess.py:93} INFO - 
[2025-07-30T20:11:00.601+0000] {subprocess.py:93} INFO - During handling of the above exception, another exception occurred:
[2025-07-30T20:11:00.602+0000] {subprocess.py:93} INFO - 
[2025-07-30T20:11:00.602+0000] {subprocess.py:93} INFO - Traceback (most recent call last):
[2025-07-30T20:11:00.603+0000] {subprocess.py:93} INFO -   File "/home/airflow/.local/lib/python3.8/site-packages/urllib3/connectionpool.py", line 715, in urlopen
[2025-07-30T20:11:00.603+0000] {subprocess.py:93} INFO -     httplib_response = self._make_request(
[2025-07-30T20:11:00.604+0000] {subprocess.py:93} INFO -   File "/home/airflow/.local/lib/python3.8/site-packages/urllib3/connectionpool.py", line 416, in _make_request
[2025-07-30T20:11:00.604+0000] {subprocess.py:93} INFO -     conn.request(method, url, **httplib_request_kw)
[2025-07-30T20:11:00.605+0000] {subprocess.py:93} INFO -   File "/home/airflow/.local/lib/python3.8/site-packages/urllib3/connection.py", line 244, in request
[2025-07-30T20:11:00.605+0000] {subprocess.py:93} INFO -     super(HTTPConnection, self).request(method, url, body=body, headers=headers)
[2025-07-30T20:11:00.606+0000] {subprocess.py:93} INFO -   File "/usr/local/lib/python3.8/http/client.py", line 1256, in request
[2025-07-30T20:11:00.606+0000] {subprocess.py:93} INFO -     self._send_request(method, url, body, headers, encode_chunked)
[2025-07-30T20:11:00.607+0000] {subprocess.py:93} INFO -   File "/usr/local/lib/python3.8/http/client.py", line 1302, in _send_request
[2025-07-30T20:11:00.607+0000] {subprocess.py:93} INFO -     self.endheaders(body, encode_chunked=encode_chunked)
[2025-07-30T20:11:00.608+0000] {subprocess.py:93} INFO -   File "/usr/local/lib/python3.8/http/client.py", line 1251, in endheaders
[2025-07-30T20:11:00.608+0000] {subprocess.py:93} INFO -     self._send_output(message_body, encode_chunked=encode_chunked)
[2025-07-30T20:11:00.609+0000] {subprocess.py:93} INFO -   File "/usr/local/lib/python3.8/http/client.py", line 1011, in _send_output
[2025-07-30T20:11:00.610+0000] {subprocess.py:93} INFO -     self.send(msg)
[2025-07-30T20:11:00.610+0000] {subprocess.py:93} INFO -   File "/usr/local/lib/python3.8/http/client.py", line 951, in send
[2025-07-30T20:11:00.611+0000] {subprocess.py:93} INFO -     self.connect()
[2025-07-30T20:11:00.610+0000] {subprocess.py:93} INFO -   File "/home/airflow/.local/lib/python3.8/site-packages/urllib3/connection.py", line 205, in connect
[2025-07-30T20:11:00.611+0000] {subprocess.py:93} INFO -     conn = self._new_conn()
[2025-07-30T20:11:00.611+0000] {subprocess.py:93} INFO -   File "/home/airflow/.local/lib/python3.8/site-packages/urllib3/connection.py", line 186, in _new_conn
[2025-07-30T20:11:00.612+0000] {subprocess.py:93} INFO -     raise NewConnectionError(
[2025-07-30T20:11:00.612+0000] {subprocess.py:93} INFO - urllib3.exceptions.NewConnectionError: <urllib3.connection.HTTPConnection object at 0x7f66975b5730>: Failed to establish a new connection: [Errno 111] Connection refused
[2025-07-30T20:11:00.613+0000] {subprocess.py:93} INFO - 
[2025-07-30T20:11:00.613+0000] {subprocess.py:93} INFO - During handling of the above exception, another exception occurred:
[2025-07-30T20:11:00.614+0000] {subprocess.py:93} INFO - 
[2025-07-30T20:11:00.614+0000] {subprocess.py:93} INFO - Traceback (most recent call last):
[2025-07-30T20:11:00.615+0000] {subprocess.py:93} INFO -   File "/opt/airflow/scripts/01_local_a_bronze.py", line 13, in <module>
[2025-07-30T20:11:00.615+0000] {subprocess.py:93} INFO -     if not client.bucket_exists(bucket_name):
[2025-07-30T20:11:00.616+0000] {subprocess.py:93} INFO -   File "/home/airflow/.local/lib/python3.8/site-packages/minio/api.py", line 696, in bucket_exists
[2025-07-30T20:11:00.616+0000] {subprocess.py:93} INFO -     self._execute("HEAD", bucket_name)
[2025-07-30T20:11:00.617+0000] {subprocess.py:93} INFO -   File "/home/airflow/.local/lib/python3.8/site-packages/minio/api.py", line 437, in _execute
[2025-07-30T20:11:00.617+0000] {subprocess.py:93} INFO -     region = self._get_region(bucket_name)
[2025-07-30T20:11:00.618+0000] {subprocess.py:93} INFO -   File "/home/airflow/.local/lib/python3.8/site-packages/minio/api.py", line 494, in _get_region
[2025-07-30T20:11:00.618+0000] {subprocess.py:93} INFO -     response = self._url_open(
[2025-07-30T20:11:00.619+0000] {subprocess.py:93} INFO -   File "/home/airflow/.local/lib/python3.8/site-packages/minio/api.py", line 302, in _url_open
[2025-07-30T20:11:00.619+0000] {subprocess.py:93} INFO -     response = self._http.urlopen(
[2025-07-30T20:11:00.620+0000] {subprocess.py:93} INFO -   File "/home/airflow/.local/lib/python3.8/site-packages/urllib3/poolmanager.py", line 376, in urlopen
[2025-07-30T20:11:00.620+0000] {subprocess.py:93} INFO -     response = conn.urlopen(method, u.request_uri, **kw)
[2025-07-30T20:11:00.621+0000] {subprocess.py:93} INFO -   File "/home/airflow/.local/lib/python3.8/site-packages/urllib3/connectionpool.py", line 827, in urlopen
[2025-07-30T20:11:00.621+0000] {subprocess.py:93} INFO -     return self.urlopen(
[2025-07-30T20:11:00.622+0000] {subprocess.py:93} INFO -   File "/home/airflow/.local/lib/python3.8/site-packages/urllib3/connectionpool.py", line 827, in urlopen
[2025-07-30T20:11:00.622+0000] {subprocess.py:93} INFO -     return self.urlopen(
[2025-07-30T20:11:00.623+0000] {subprocess.py:93} INFO -   File "/home/airflow/.local/lib/python3.8/site-packages/urllib3/connectionpool.py", line 827, in urlopen
[2025-07-30T20:11:00.623+0000] {subprocess.py:93} INFO -     return self.urlopen(
[2025-07-30T20:11:00.623+0000] {subprocess.py:93} INFO -   [Previous line repeated 2 more times]
[2025-07-30T20:11:00.624+0000] {subprocess.py:93} INFO -   File "/home/airflow/.local/lib/python3.8/site-packages/urllib3/connectionpool.py", line 799, in urlopen
[2025-07-30T20:11:00.624+0000] {subprocess.py:93} INFO -     retries = retries.increment(
[2025-07-30T20:11:00.625+0000] {subprocess.py:93} INFO -   File "/home/airflow/.local/lib/python3.8/site-packages/urllib3/util/retry.py", line 592, in increment
[2025-07-30T20:11:00.625+0000] {subprocess.py:93} INFO -     raise MaxRetryError(_pool, url, error or ResponseError(cause))
[2025-07-30T20:11:00.626+0000] {subprocess.py:93} INFO - urllib3.exceptions.MaxRetryError: HTTPConnectionPool(host='localhost', port=9000): Max retries exceeded with url: /dev-local-bronze?location= (Caused by NewConnectionError('<urllib3.connection.HTTPConnection object at 0x7f66975b5730>: Failed to establish a new connection: [Errno 111] Connection refused'))
[2025-07-30T20:11:00.626+0000] {subprocess.py:97} INFO - Command exited with return code 1
[2025-07-30T20:11:00.641+0000] {taskinstance.py:2698} ERROR - Task failed with exception
Traceback (most recent call last):
  File "/home/airflow/.local/lib/python3.8/site-packages/airflow/models/taskinstance.py", line 433, in _execute_task
    result = execute_callable(context=context, **execute_callable_kwargs)
  File "/home/airflow/.local/lib/python3.8/site-packages/airflow/operators/bash.py", line 212, in execute
    raise AirflowException(
airflow.exceptions.AirflowException: Bash command failed. The command returned a non-zero exit code 1.
[2025-07-30T20:11:00.647+0000] {taskinstance.py:1138} INFO - Marking task as FAILED. dag_id=pipeline_medallon, task_id=cargar_bronze, execution_date=20250730T200359, start_date=20250730T201054, end_date=20250730T201100
[2025-07-30T20:11:00.718+0000] {standard_task_runner.py:107} ERROR - Failed to execute job 4 for task cargar_bronze (Bash command failed. The command returned a non-zero exit code 1.; 165)
[2025-07-30T20:11:00.733+0000] {local_task_job_runner.py:234} INFO - Task exited with return code 1
[2025-07-30T20:11:00.770+0000] {taskinstance.py:3280} INFO - 0 downstream tasks scheduled from follow-on schedule check
