[2025-07-30T20:51:22.022+0000] {taskinstance.py:1956} INFO - Dependencies all met for dep_context=non-requeueable deps ti=<TaskInstance: pipeline_medallon.crea_esquema_publico manual__2025-07-30T20:51:17.349884+00:00 [queued]>
[2025-07-30T20:51:22.104+0000] {taskinstance.py:1956} INFO - Dependencies all met for dep_context=requeueable deps ti=<TaskInstance: pipeline_medallon.crea_esquema_publico manual__2025-07-30T20:51:17.349884+00:00 [queued]>
[2025-07-30T20:51:22.104+0000] {taskinstance.py:2170} INFO - Starting attempt 1 of 2
[2025-07-30T20:51:22.139+0000] {taskinstance.py:2191} INFO - Executing <Task(BashOperator): crea_esquema_publico> on 2025-07-30 20:51:17.349884+00:00
[2025-07-30T20:51:22.143+0000] {standard_task_runner.py:60} INFO - Started process 56 to run task
[2025-07-30T20:51:22.147+0000] {standard_task_runner.py:87} INFO - Running: ['airflow', 'tasks', 'run', 'pipeline_medallon', 'crea_esquema_publico', 'manual__2025-07-30T20:51:17.349884+00:00', '--job-id', '9', '--raw', '--subdir', 'DAGS_FOLDER/pipeline_medallon_dag.py', '--cfg-path', '/tmp/tmpgwbizeho']
[2025-07-30T20:51:22.149+0000] {standard_task_runner.py:88} INFO - Job 9: Subtask crea_esquema_publico
[2025-07-30T20:51:22.232+0000] {task_command.py:423} INFO - Running <TaskInstance: pipeline_medallon.crea_esquema_publico manual__2025-07-30T20:51:17.349884+00:00 [running]> on host 70eaa744a05c
[2025-07-30T20:51:22.359+0000] {taskinstance.py:2480} INFO - Exporting env vars: AIRFLOW_CTX_DAG_OWNER='mateo.biasotto' AIRFLOW_CTX_DAG_ID='pipeline_medallon' AIRFLOW_CTX_TASK_ID='crea_esquema_publico' AIRFLOW_CTX_EXECUTION_DATE='2025-07-30T20:51:17.349884+00:00' AIRFLOW_CTX_TRY_NUMBER='1' AIRFLOW_CTX_DAG_RUN_ID='manual__2025-07-30T20:51:17.349884+00:00'
[2025-07-30T20:51:22.360+0000] {subprocess.py:63} INFO - Tmp dir root location: /tmp
[2025-07-30T20:51:22.361+0000] {subprocess.py:75} INFO - Running command: ['/usr/bin/bash', '-c', 'python3 /opt/airflow/scripts/01_crea_esquema_publico.py']
[2025-07-30T20:51:22.368+0000] {subprocess.py:86} INFO - Output:
[2025-07-30T20:51:22.395+0000] {subprocess.py:93} INFO - python3: can't open file '/opt/airflow/scripts/01_crea_esquema_publico.py': [Errno 2] No such file or directory
[2025-07-30T20:51:22.398+0000] {subprocess.py:97} INFO - Command exited with return code 2
[2025-07-30T20:51:22.412+0000] {taskinstance.py:2698} ERROR - Task failed with exception
Traceback (most recent call last):
  File "/home/airflow/.local/lib/python3.8/site-packages/airflow/models/taskinstance.py", line 433, in _execute_task
    result = execute_callable(context=context, **execute_callable_kwargs)
  File "/home/airflow/.local/lib/python3.8/site-packages/airflow/operators/bash.py", line 212, in execute
    raise AirflowException(
airflow.exceptions.AirflowException: Bash command failed. The command returned a non-zero exit code 2.
[2025-07-30T20:51:22.416+0000] {taskinstance.py:1138} INFO - Marking task as UP_FOR_RETRY. dag_id=pipeline_medallon, task_id=crea_esquema_publico, execution_date=20250730T205117, start_date=20250730T205122, end_date=20250730T205122
[2025-07-30T20:51:22.448+0000] {standard_task_runner.py:107} ERROR - Failed to execute job 9 for task crea_esquema_publico (Bash command failed. The command returned a non-zero exit code 2.; 56)
[2025-07-30T20:51:22.480+0000] {local_task_job_runner.py:234} INFO - Task exited with return code 1
[2025-07-30T20:51:22.515+0000] {taskinstance.py:3280} INFO - 0 downstream tasks scheduled from follow-on schedule check
