[2025-08-04T15:45:31.263+0000] {taskinstance.py:1956} INFO - Dependencies all met for dep_context=non-requeueable deps ti=<TaskInstance: pipeline_medallon.ejecutar_merge manual__2025-08-04T15:39:36+00:00 [queued]>
[2025-08-04T15:45:31.293+0000] {taskinstance.py:1956} INFO - Dependencies all met for dep_context=requeueable deps ti=<TaskInstance: pipeline_medallon.ejecutar_merge manual__2025-08-04T15:39:36+00:00 [queued]>
[2025-08-04T15:45:31.293+0000] {taskinstance.py:2170} INFO - Starting attempt 1 of 2
[2025-08-04T15:45:31.377+0000] {taskinstance.py:2191} INFO - Executing <Task(PostgresOperator): ejecutar_merge> on 2025-08-04 15:39:36+00:00
[2025-08-04T15:45:31.382+0000] {standard_task_runner.py:60} INFO - Started process 255 to run task
[2025-08-04T15:45:31.385+0000] {standard_task_runner.py:87} INFO - Running: ['airflow', 'tasks', 'run', 'pipeline_medallon', 'ejecutar_merge', 'manual__2025-08-04T15:39:36+00:00', '--job-id', '192', '--raw', '--subdir', 'DAGS_FOLDER/pipeline_medallon_dag.py', '--cfg-path', '/tmp/tmp7sm0gs10']
[2025-08-04T15:45:31.387+0000] {standard_task_runner.py:88} INFO - Job 192: Subtask ejecutar_merge
[2025-08-04T15:45:31.470+0000] {task_command.py:423} INFO - Running <TaskInstance: pipeline_medallon.ejecutar_merge manual__2025-08-04T15:39:36+00:00 [running]> on host 70eaa744a05c
[2025-08-04T15:45:31.636+0000] {taskinstance.py:2480} INFO - Exporting env vars: AIRFLOW_CTX_DAG_OWNER='mateo.biasotto' AIRFLOW_CTX_DAG_ID='pipeline_medallon' AIRFLOW_CTX_TASK_ID='ejecutar_merge' AIRFLOW_CTX_EXECUTION_DATE='2025-08-04T15:39:36+00:00' AIRFLOW_CTX_TRY_NUMBER='1' AIRFLOW_CTX_DAG_RUN_ID='manual__2025-08-04T15:39:36+00:00'
[2025-08-04T15:45:31.637+0000] {sql.py:276} INFO - Executing: CALL merge_bulk_to_final();
[2025-08-04T15:45:31.649+0000] {base.py:83} INFO - Using connection ID 'postgres_medallon' for task execution.
[2025-08-04T15:45:31.739+0000] {base.py:83} INFO - Using connection ID 'postgres_medallon' for task execution.
[2025-08-04T15:45:31.765+0000] {sql.py:450} INFO - Running statement: CALL merge_bulk_to_final();, parameters: None
[2025-08-04T15:45:32.038+0000] {taskinstance.py:2698} ERROR - Task failed with exception
Traceback (most recent call last):
  File "/home/airflow/.local/lib/python3.8/site-packages/airflow/models/taskinstance.py", line 433, in _execute_task
    result = execute_callable(context=context, **execute_callable_kwargs)
  File "/home/airflow/.local/lib/python3.8/site-packages/airflow/providers/common/sql/operators/sql.py", line 282, in execute
    output = hook.run(
  File "/home/airflow/.local/lib/python3.8/site-packages/airflow/providers/common/sql/hooks/sql.py", line 398, in run
    self._run_command(cur, sql_statement, parameters)
  File "/home/airflow/.local/lib/python3.8/site-packages/airflow/providers/common/sql/hooks/sql.py", line 455, in _run_command
    cur.execute(sql_statement)
psycopg2.errors.ForeignKeyViolation: insert or update on table "fact_ventas" violates foreign key constraint "fact_ventas_customer_id_fkey"
DETAIL:  Key (customer_id)=(DK-13375) is not present in table "dim_cliente".
CONTEXT:  SQL statement "INSERT INTO staging.fact_ventas
    SELECT DISTINCT ON (order_id || '-' || product_id)
        order_id || '-' || product_id AS taligent_id,
        order_id,
        order_date,
        ship_date,
        customer_id,
        product_id,
        sales,
        quantity,
        discount,
        profit
    FROM public.bulk_fact_ventas
    ORDER BY order_id || '-' || product_id
    ON CONFLICT (taligent_id) DO UPDATE
    SET order_date  = EXCLUDED.order_date,
        ship_date   = EXCLUDED.ship_date,
        customer_id = EXCLUDED.customer_id,
        product_id  = EXCLUDED.product_id,
        sales       = EXCLUDED.sales,
        quantity    = EXCLUDED.quantity,
        discount    = EXCLUDED.discount,
        profit      = EXCLUDED.profit"
PL/pgSQL function merge_bulk_to_final() line 32 at SQL statement

[2025-08-04T15:45:32.070+0000] {taskinstance.py:1138} INFO - Marking task as UP_FOR_RETRY. dag_id=pipeline_medallon, task_id=ejecutar_merge, execution_date=20250804T153936, start_date=20250804T154531, end_date=20250804T154532
[2025-08-04T15:45:32.115+0000] {standard_task_runner.py:107} ERROR - Failed to execute job 192 for task ejecutar_merge (insert or update on table "fact_ventas" violates foreign key constraint "fact_ventas_customer_id_fkey"
DETAIL:  Key (customer_id)=(DK-13375) is not present in table "dim_cliente".
CONTEXT:  SQL statement "INSERT INTO staging.fact_ventas
    SELECT DISTINCT ON (order_id || '-' || product_id)
        order_id || '-' || product_id AS taligent_id,
        order_id,
        order_date,
        ship_date,
        customer_id,
        product_id,
        sales,
        quantity,
        discount,
        profit
    FROM public.bulk_fact_ventas
    ORDER BY order_id || '-' || product_id
    ON CONFLICT (taligent_id) DO UPDATE
    SET order_date  = EXCLUDED.order_date,
        ship_date   = EXCLUDED.ship_date,
        customer_id = EXCLUDED.customer_id,
        product_id  = EXCLUDED.product_id,
        sales       = EXCLUDED.sales,
        quantity    = EXCLUDED.quantity,
        discount    = EXCLUDED.discount,
        profit      = EXCLUDED.profit"
PL/pgSQL function merge_bulk_to_final() line 32 at SQL statement
; 255)
[2025-08-04T15:45:32.161+0000] {local_task_job_runner.py:234} INFO - Task exited with return code 1
[2025-08-04T15:45:32.184+0000] {taskinstance.py:3280} INFO - 0 downstream tasks scheduled from follow-on schedule check
