[2025-08-04T15:50:35.127+0000] {taskinstance.py:1956} INFO - Dependencies all met for dep_context=non-requeueable deps ti=<TaskInstance: pipeline_medallon.ejecutar_merge manual__2025-08-04T15:39:36+00:00 [queued]>
[2025-08-04T15:50:35.153+0000] {taskinstance.py:1956} INFO - Dependencies all met for dep_context=requeueable deps ti=<TaskInstance: pipeline_medallon.ejecutar_merge manual__2025-08-04T15:39:36+00:00 [queued]>
[2025-08-04T15:50:35.153+0000] {taskinstance.py:2170} INFO - Starting attempt 2 of 2
[2025-08-04T15:50:35.194+0000] {taskinstance.py:2191} INFO - Executing <Task(PostgresOperator): ejecutar_merge> on 2025-08-04 15:39:36+00:00
[2025-08-04T15:50:35.198+0000] {standard_task_runner.py:60} INFO - Started process 59 to run task
[2025-08-04T15:50:35.201+0000] {standard_task_runner.py:87} INFO - Running: ['airflow', 'tasks', 'run', 'pipeline_medallon', 'ejecutar_merge', 'manual__2025-08-04T15:39:36+00:00', '--job-id', '195', '--raw', '--subdir', 'DAGS_FOLDER/pipeline_medallon_dag.py', '--cfg-path', '/tmp/tmp6xvr6apu']
[2025-08-04T15:50:35.203+0000] {standard_task_runner.py:88} INFO - Job 195: Subtask ejecutar_merge
[2025-08-04T15:50:35.295+0000] {task_command.py:423} INFO - Running <TaskInstance: pipeline_medallon.ejecutar_merge manual__2025-08-04T15:39:36+00:00 [running]> on host 70eaa744a05c
[2025-08-04T15:50:35.425+0000] {taskinstance.py:2480} INFO - Exporting env vars: AIRFLOW_CTX_DAG_OWNER='mateo.biasotto' AIRFLOW_CTX_DAG_ID='pipeline_medallon' AIRFLOW_CTX_TASK_ID='ejecutar_merge' AIRFLOW_CTX_EXECUTION_DATE='2025-08-04T15:39:36+00:00' AIRFLOW_CTX_TRY_NUMBER='2' AIRFLOW_CTX_DAG_RUN_ID='manual__2025-08-04T15:39:36+00:00'
[2025-08-04T15:50:35.426+0000] {sql.py:276} INFO - Executing: CALL merge_bulk_to_final();
[2025-08-04T15:50:35.438+0000] {base.py:83} INFO - Using connection ID 'postgres_medallon' for task execution.
[2025-08-04T15:50:35.522+0000] {base.py:83} INFO - Using connection ID 'postgres_medallon' for task execution.
[2025-08-04T15:50:35.554+0000] {sql.py:450} INFO - Running statement: CALL merge_bulk_to_final();, parameters: None
[2025-08-04T15:50:35.558+0000] {taskinstance.py:2698} ERROR - Task failed with exception
Traceback (most recent call last):
  File "/home/airflow/.local/lib/python3.8/site-packages/airflow/models/taskinstance.py", line 433, in _execute_task
    result = execute_callable(context=context, **execute_callable_kwargs)
  File "/home/airflow/.local/lib/python3.8/site-packages/airflow/providers/common/sql/operators/sql.py", line 282, in execute
    output = hook.run(
  File "/home/airflow/.local/lib/python3.8/site-packages/airflow/providers/common/sql/hooks/sql.py", line 398, in run
    self._run_command(cur, sql_statement, parameters)
  File "/home/airflow/.local/lib/python3.8/site-packages/airflow/providers/common/sql/hooks/sql.py", line 455, in _run_command
    cur.execute(sql_statement)
psycopg2.errors.UndefinedFunction: procedure merge_bulk_to_final() does not exist
LINE 1: CALL merge_bulk_to_final();
             ^
HINT:  No procedure matches the given name and argument types. You might need to add explicit type casts.

[2025-08-04T15:50:35.569+0000] {taskinstance.py:1138} INFO - Marking task as FAILED. dag_id=pipeline_medallon, task_id=ejecutar_merge, execution_date=20250804T153936, start_date=20250804T155035, end_date=20250804T155035
[2025-08-04T15:50:35.624+0000] {standard_task_runner.py:107} ERROR - Failed to execute job 195 for task ejecutar_merge (procedure merge_bulk_to_final() does not exist
LINE 1: CALL merge_bulk_to_final();
             ^
HINT:  No procedure matches the given name and argument types. You might need to add explicit type casts.
; 59)
[2025-08-04T15:50:35.657+0000] {local_task_job_runner.py:234} INFO - Task exited with return code 1
[2025-08-04T15:50:35.682+0000] {taskinstance.py:3280} INFO - 0 downstream tasks scheduled from follow-on schedule check
