[2025-07-30T20:11:03.834+0000] {taskinstance.py:1956} INFO - Dependencies all met for dep_context=non-requeueable deps ti=<TaskInstance: pipeline_medallon.cargar_bronze manual__2025-07-30T20:05:40.403127+00:00 [queued]>
[2025-07-30T20:11:03.847+0000] {taskinstance.py:1956} INFO - Dependencies all met for dep_context=requeueable deps ti=<TaskInstance: pipeline_medallon.cargar_bronze manual__2025-07-30T20:05:40.403127+00:00 [queued]>
[2025-07-30T20:11:03.848+0000] {taskinstance.py:2170} INFO - Starting attempt 2 of 2
[2025-07-30T20:11:03.889+0000] {taskinstance.py:2191} INFO - Executing <Task(BashOperator): cargar_bronze> on 2025-07-30 20:05:40.403127+00:00
[2025-07-30T20:11:03.893+0000] {standard_task_runner.py:60} INFO - Started process 177 to run task
[2025-07-30T20:11:03.898+0000] {standard_task_runner.py:87} INFO - Running: ['airflow', 'tasks', 'run', 'pipeline_medallon', 'cargar_bronze', 'manual__2025-07-30T20:05:40.403127+00:00', '--job-id', '5', '--raw', '--subdir', 'DAGS_FOLDER/pipeline_medallon_dag.py', '--cfg-path', '/tmp/tmpbfyjw5d7']
[2025-07-30T20:11:03.901+0000] {standard_task_runner.py:88} INFO - Job 5: Subtask cargar_bronze
[2025-07-30T20:11:03.990+0000] {task_command.py:423} INFO - Running <TaskInstance: pipeline_medallon.cargar_bronze manual__2025-07-30T20:05:40.403127+00:00 [running]> on host 2a163dc77c1e
[2025-07-30T20:11:04.092+0000] {taskinstance.py:2480} INFO - Exporting env vars: AIRFLOW_CTX_DAG_OWNER='mateo.biasotto' AIRFLOW_CTX_DAG_ID='pipeline_medallon' AIRFLOW_CTX_TASK_ID='cargar_bronze' AIRFLOW_CTX_EXECUTION_DATE='2025-07-30T20:05:40.403127+00:00' AIRFLOW_CTX_TRY_NUMBER='2' AIRFLOW_CTX_DAG_RUN_ID='manual__2025-07-30T20:05:40.403127+00:00'
[2025-07-30T20:11:04.093+0000] {subprocess.py:63} INFO - Tmp dir root location: /tmp
[2025-07-30T20:11:04.094+0000] {subprocess.py:75} INFO - Running command: ['/usr/bin/bash', '-c', 'python3 /opt/airflow/scripts/01_local_a_bronze.py']
[2025-07-30T20:11:04.100+0000] {subprocess.py:86} INFO - Output:
[2025-07-30T20:11:10.346+0000] {subprocess.py:93} INFO - Traceback (most recent call last):
[2025-07-30T20:11:10.347+0000] {subprocess.py:93} INFO -   File "/home/airflow/.local/lib/python3.8/site-packages/urllib3/connection.py", line 174, in _new_conn
[2025-07-30T20:11:10.347+0000] {subprocess.py:93} INFO -     conn = connection.create_connection(
[2025-07-30T20:11:10.348+0000] {subprocess.py:93} INFO -   File "/home/airflow/.local/lib/python3.8/site-packages/urllib3/util/connection.py", line 95, in create_connection
[2025-07-30T20:11:10.348+0000] {subprocess.py:93} INFO -     raise err
[2025-07-30T20:11:10.349+0000] {subprocess.py:93} INFO -   File "/home/airflow/.local/lib/python3.8/site-packages/urllib3/util/connection.py", line 85, in create_connection
[2025-07-30T20:11:10.349+0000] {subprocess.py:93} INFO -     sock.connect(sa)
[2025-07-30T20:11:10.350+0000] {subprocess.py:93} INFO - ConnectionRefusedError: [Errno 111] Connection refused
[2025-07-30T20:11:10.350+0000] {subprocess.py:93} INFO - 
[2025-07-30T20:11:10.351+0000] {subprocess.py:93} INFO - During handling of the above exception, another exception occurred:
[2025-07-30T20:11:10.351+0000] {subprocess.py:93} INFO - 
[2025-07-30T20:11:10.352+0000] {subprocess.py:93} INFO - Traceback (most recent call last):
[2025-07-30T20:11:10.352+0000] {subprocess.py:93} INFO -   File "/home/airflow/.local/lib/python3.8/site-packages/urllib3/connectionpool.py", line 715, in urlopen
[2025-07-30T20:11:10.353+0000] {subprocess.py:93} INFO -     httplib_response = self._make_request(
[2025-07-30T20:11:10.353+0000] {subprocess.py:93} INFO -   File "/home/airflow/.local/lib/python3.8/site-packages/urllib3/connectionpool.py", line 416, in _make_request
[2025-07-30T20:11:10.354+0000] {subprocess.py:93} INFO -     conn.request(method, url, **httplib_request_kw)
[2025-07-30T20:11:10.354+0000] {subprocess.py:93} INFO -   File "/home/airflow/.local/lib/python3.8/site-packages/urllib3/connection.py", line 244, in request
[2025-07-30T20:11:10.355+0000] {subprocess.py:93} INFO -     super(HTTPConnection, self).request(method, url, body=body, headers=headers)
[2025-07-30T20:11:10.355+0000] {subprocess.py:93} INFO -   File "/usr/local/lib/python3.8/http/client.py", line 1256, in request
[2025-07-30T20:11:10.356+0000] {subprocess.py:93} INFO -     self._send_request(method, url, body, headers, encode_chunked)
[2025-07-30T20:11:10.356+0000] {subprocess.py:93} INFO -   File "/usr/local/lib/python3.8/http/client.py", line 1302, in _send_request
[2025-07-30T20:11:10.357+0000] {subprocess.py:93} INFO -     self.endheaders(body, encode_chunked=encode_chunked)
[2025-07-30T20:11:10.357+0000] {subprocess.py:93} INFO -   File "/usr/local/lib/python3.8/http/client.py", line 1251, in endheaders
[2025-07-30T20:11:10.357+0000] {subprocess.py:93} INFO -     self._send_output(message_body, encode_chunked=encode_chunked)
[2025-07-30T20:11:10.358+0000] {subprocess.py:93} INFO -   File "/usr/local/lib/python3.8/http/client.py", line 1011, in _send_output
[2025-07-30T20:11:10.358+0000] {subprocess.py:93} INFO -     self.send(msg)
[2025-07-30T20:11:10.359+0000] {subprocess.py:93} INFO -   File "/usr/local/lib/python3.8/http/client.py", line 951, in send
[2025-07-30T20:11:10.360+0000] {subprocess.py:93} INFO -     self.connect()
[2025-07-30T20:11:10.360+0000] {subprocess.py:93} INFO -   File "/home/airflow/.local/lib/python3.8/site-packages/urllib3/connection.py", line 205, in connect
[2025-07-30T20:11:10.361+0000] {subprocess.py:93} INFO -     conn = self._new_conn()
[2025-07-30T20:11:10.361+0000] {subprocess.py:93} INFO -   File "/home/airflow/.local/lib/python3.8/site-packages/urllib3/connection.py", line 186, in _new_conn
[2025-07-30T20:11:10.362+0000] {subprocess.py:93} INFO -     raise NewConnectionError(
[2025-07-30T20:11:10.362+0000] {subprocess.py:93} INFO - urllib3.exceptions.NewConnectionError: <urllib3.connection.HTTPConnection object at 0x7fc67f8b0730>: Failed to establish a new connection: [Errno 111] Connection refused
[2025-07-30T20:11:10.363+0000] {subprocess.py:93} INFO - 
[2025-07-30T20:11:10.364+0000] {subprocess.py:93} INFO - During handling of the above exception, another exception occurred:
[2025-07-30T20:11:10.364+0000] {subprocess.py:93} INFO - 
[2025-07-30T20:11:10.364+0000] {subprocess.py:93} INFO - Traceback (most recent call last):
[2025-07-30T20:11:10.365+0000] {subprocess.py:93} INFO -   File "/opt/airflow/scripts/01_local_a_bronze.py", line 13, in <module>
[2025-07-30T20:11:10.365+0000] {subprocess.py:93} INFO -     if not client.bucket_exists(bucket_name):
[2025-07-30T20:11:10.366+0000] {subprocess.py:93} INFO -   File "/home/airflow/.local/lib/python3.8/site-packages/minio/api.py", line 696, in bucket_exists
[2025-07-30T20:11:10.366+0000] {subprocess.py:93} INFO -     self._execute("HEAD", bucket_name)
[2025-07-30T20:11:10.366+0000] {subprocess.py:93} INFO -   File "/home/airflow/.local/lib/python3.8/site-packages/minio/api.py", line 437, in _execute
[2025-07-30T20:11:10.367+0000] {subprocess.py:93} INFO -     region = self._get_region(bucket_name)
[2025-07-30T20:11:10.367+0000] {subprocess.py:93} INFO -   File "/home/airflow/.local/lib/python3.8/site-packages/minio/api.py", line 494, in _get_region
[2025-07-30T20:11:10.368+0000] {subprocess.py:93} INFO -     response = self._url_open(
[2025-07-30T20:11:10.368+0000] {subprocess.py:93} INFO -   File "/home/airflow/.local/lib/python3.8/site-packages/minio/api.py", line 302, in _url_open
[2025-07-30T20:11:10.368+0000] {subprocess.py:93} INFO -     response = self._http.urlopen(
[2025-07-30T20:11:10.369+0000] {subprocess.py:93} INFO -   File "/home/airflow/.local/lib/python3.8/site-packages/urllib3/poolmanager.py", line 376, in urlopen
[2025-07-30T20:11:10.369+0000] {subprocess.py:93} INFO -     response = conn.urlopen(method, u.request_uri, **kw)
[2025-07-30T20:11:10.369+0000] {subprocess.py:93} INFO -   File "/home/airflow/.local/lib/python3.8/site-packages/urllib3/connectionpool.py", line 827, in urlopen
[2025-07-30T20:11:10.370+0000] {subprocess.py:93} INFO -     return self.urlopen(
[2025-07-30T20:11:10.370+0000] {subprocess.py:93} INFO -   File "/home/airflow/.local/lib/python3.8/site-packages/urllib3/connectionpool.py", line 827, in urlopen
[2025-07-30T20:11:10.371+0000] {subprocess.py:93} INFO -     return self.urlopen(
[2025-07-30T20:11:10.371+0000] {subprocess.py:93} INFO -   File "/home/airflow/.local/lib/python3.8/site-packages/urllib3/connectionpool.py", line 827, in urlopen
[2025-07-30T20:11:10.371+0000] {subprocess.py:93} INFO -     return self.urlopen(
[2025-07-30T20:11:10.372+0000] {subprocess.py:93} INFO -   [Previous line repeated 2 more times]
[2025-07-30T20:11:10.372+0000] {subprocess.py:93} INFO -   File "/home/airflow/.local/lib/python3.8/site-packages/urllib3/connectionpool.py", line 799, in urlopen
[2025-07-30T20:11:10.372+0000] {subprocess.py:93} INFO -     retries = retries.increment(
[2025-07-30T20:11:10.373+0000] {subprocess.py:93} INFO -   File "/home/airflow/.local/lib/python3.8/site-packages/urllib3/util/retry.py", line 592, in increment
[2025-07-30T20:11:10.373+0000] {subprocess.py:93} INFO -     raise MaxRetryError(_pool, url, error or ResponseError(cause))
[2025-07-30T20:11:10.373+0000] {subprocess.py:93} INFO - urllib3.exceptions.MaxRetryError: HTTPConnectionPool(host='localhost', port=9000): Max retries exceeded with url: /dev-local-bronze?location= (Caused by NewConnectionError('<urllib3.connection.HTTPConnection object at 0x7fc67f8b0730>: Failed to establish a new connection: [Errno 111] Connection refused'))
[2025-07-30T20:11:10.373+0000] {subprocess.py:97} INFO - Command exited with return code 1
[2025-07-30T20:11:10.384+0000] {taskinstance.py:2698} ERROR - Task failed with exception
Traceback (most recent call last):
  File "/home/airflow/.local/lib/python3.8/site-packages/airflow/models/taskinstance.py", line 433, in _execute_task
    result = execute_callable(context=context, **execute_callable_kwargs)
  File "/home/airflow/.local/lib/python3.8/site-packages/airflow/operators/bash.py", line 212, in execute
    raise AirflowException(
airflow.exceptions.AirflowException: Bash command failed. The command returned a non-zero exit code 1.
[2025-07-30T20:11:10.387+0000] {taskinstance.py:1138} INFO - Marking task as FAILED. dag_id=pipeline_medallon, task_id=cargar_bronze, execution_date=20250730T200540, start_date=20250730T201103, end_date=20250730T201110
[2025-07-30T20:11:10.454+0000] {standard_task_runner.py:107} ERROR - Failed to execute job 5 for task cargar_bronze (Bash command failed. The command returned a non-zero exit code 1.; 177)
[2025-07-30T20:11:10.493+0000] {local_task_job_runner.py:234} INFO - Task exited with return code 1
[2025-07-30T20:11:10.525+0000] {taskinstance.py:3280} INFO - 0 downstream tasks scheduled from follow-on schedule check
